Workbook

Sheet ميزان المراجعه
C4: كود الحساب | D4: اسم الحساب | E4: طبيعه الحساب | F4: القائمه | G4: المستوي | H4: نوع الحساب | I4: رصيد اول المده | K4: حركه الفتره | M4: رصيد اخر المده | P4: التبويب بالقائمه | Q4: التبويب الرئيسي
I5: مدين | J5: دائن | K5: مدين | L5: دائن | M5: مدين | N5: دائن | O5: الصافي
C6: 1 | D6: الاصول | E6: مدين | F6: المركز المالي | G6: 1 | H6: رئيسي
C7: 11 | D7: اصول غير متداوله | E7: مدين | F7: المركز المالي | G7: 2 | H7: رئيسي
C8: 111 | D8: الاصول الثابته | E8: مدين | F8: المركز المالي | G8: 3 | H8: رئيسي
C9: 111000 | D9: الاراضي | E9: مدين | F9: المركز المالي | G9: 4 | H9: فرعي | K9: =SUMIF('قيود اليوميه'!G:G,'ميزان المراجعه'!C9,'قيود اليوميه'!D:D) -> 0 | M9: =IF(I9-J9+K9-L9>0,I9-J9+K9-L9,"") | N9: =IF(J9-I9+L9-K9>0,J9-I9+L9-K9,"") | O9: =IFERROR(IF(N9<>"",N9,M9*-1),"") | P9: الاصول الثابته | Q9: اصول غير متداوله
C10: 111001 | D10: المباني | E10: مدين | F10: المركز المالي | G10: 4 | H10: فرعي | K10: =SUMIF('قيود اليوميه'!G:G,'ميزان المراجعه'!C10,'قيود اليوميه'!D:D) -> 0 | L10: =SUMIF('قيود اليوميه'!G:G,'ميزان المراجعه'!C10,'قيود اليوميه'!E:E) -> 0 | M10: =IF(I10-J10+K10-L10>0,I10-J10+K10-L10,"") | N10: =IF(J10-I10+L10-K10>0,J10-I10+L10-K10,"") | O10: =IFERROR(IF(N10<>"",N10,M10*-1),"") | P10: الاصول الثابته | Q10: اصول غير متداوله
C11: 111002 | D11: الاثاث والمعدات | E11: مدين | F11: المركز المالي | G11: 4 | H11: فرعي | K11: =SUMIF('قيود اليوميه'!G:G,'ميزان المراجعه'!C11,'قيود اليوميه'!D:D) -> 75000 | L11: =SUMIF('قيود اليوميه'!G:G,'ميزان المراجعه'!C11,'قيود اليوميه'!E:E) -> 0 | M11: =IF(I11-J11+K11-L11>0,I11-J11+K11-L11,"") -> 75000 | N11: =IF(J11-I11+L11-K11>0,J11-I11+L11-K11,"") | O11: =IFERROR(IF(N11<>"",N11,M11*-1),"") -> -75000 | P11: الاصول الثابته | Q11: اصول غير متداوله
C12: 111003 | D12: السيارات | E12: مدين | F12: المركز المالي | G12: 4 | H12: فرعي | K12: =SUMIF('قيود اليوميه'!G:G,'ميزان المراجعه'!C12,'قيود اليوميه'!D:D) -> 100000 | L12: =SUMIF('قيود اليوميه'!G:G,'ميزان المراجعه'!C12,'قيود اليوميه'!E:E) -> 0 | M12: =IF(I12-J12+K12-L12>0,I12-J12+K12-L12,"") -> 100000 | N12: =IF(J12-I12+L12-K12>0,J12-I12+L12-K12,"") | O12: =IFERROR(IF(N12<>"",N12,M12*-1),"") -> -100000 | P12: الاصول الثابته | Q12: اصول غير متداوله
C13: 111004 | D13: اجهزه الحاسب | E13: مدين | F13: المركز المالي | G13: 4 | H13: فرعي | K13: =SUMIF('قيود اليوميه'!G:G,'ميزان المراجعه'!C13,'قيود اليوميه'!D:D) -> 50000 | L13: =SUMIF('قيود اليوميه'!G:G,'ميزان المراجعه'!C13,'قيود اليوميه'!E:E) -> 0 | M13: =IF(I13-J13+K13-L13>0,I13-J13+K13-L13,"") -> 50000 | N13: =IF(J13-I13+L13-K13>0,J13-I13+L13-K13,"") | O13: =IFERROR(IF(N13<>"",N13,M13*-1),"") -> -50000 | P13: الاصول الثابته | Q13: اصول غير متداوله
C14: 111005 | D14: مجمع الاهلاك | E14: دائن | F14: المركز المالي | G14: 4 | H14: فرعي | K14: =SUMIF('قيود اليوميه'!G:G,'ميزان المراجعه'!C14,'قيود اليوميه'!D:D) -> 0 | L14: =SUMIF('قيود اليوميه'!G:G,'ميزان المراجعه'!C14,'قيود اليوميه'!E:E) -> 16250 | M14: =IF(I14-J14+K14-L14>0,I14-J14+K14-L14,"") | N14: =IF(J14-I14+L14-K14>0,J14-I14+L14-K14,"") -> 16250 | O14: =IFERROR(IF(N14<>"",N14,M14*-1),"") -> 16250 | P14: الاصول الثابته | Q14: اصول غير متداوله
C15: 112 | D15: الاستثمارات طويله الاجل | E15: مدين | F15: المركز المالي | G15: 3 | H15: رئيسي
C16: 112000 | D16: استثمارات في شركات شقيقه | E16: مدين | F16: المركز المالي | G16: 4 | H16: فرعي | K16: =SUMIF('قيود اليوميه'!G:G,'ميزان المراجعه'!C16,'قيود اليوميه'!D:D) -> 0 | L16: =SUMIF('قيود اليوميه'!G:G,'ميزان المراجعه'!C16,'قيود اليوميه'!E:E) -> 0 | M16: =IF(I16-J16+K16-L16>0,I16-J16+K16-L16,"") | N16: =IF(J16-I16+L16-K16>0,J16-I16+L16-K16,"") | O16: =IFERROR(IF(N16<>"",N16,M16*-1),"") | P16: الاستثمارات طويله الاجل | Q16: اصول غير متداوله
C17: 112001 | D17: سندات طويله الاجل | E17: مدين | F17: المركز المالي | G17: 4 | H17: فرعي | K17: =SUMIF('قيود اليوميه'!G:G,'ميزان المراجعه'!C17,'قيود اليوميه'!D:D) -> 0 | L17: =SUMIF('قيود اليوميه'!G:G,'ميزان المراجعه'!C17,'قيود اليوميه'!E:E) -> 0 | M17: =IF(I17-J17+K17-L17>0,I17-J17+K17-L17,"") | N17: =IF(J17-I17+L17-K17>0,J17-I17+L17-K17,"") | O17: =IFERROR(IF(N17<>"",N17,M17*-1),"") | P17: الاستثمارات طويله الاجل | Q17: اصول غير متداوله
C18: 113 | D18: الودائع والتامينات طويله الاجل | E18: مدين | F18: المركز المالي | G18: 3 | H18: رئيسي
C19: 113000 | D19: ودائع وتأمينات طويله الاجل | E19: مدين | F19: المركز المالي | G19: 4 | H19: فرعي | K19: =SUMIF('قيود اليوميه'!G:G,'ميزان المراجعه'!C19,'قيود اليوميه'!D:D) -> 0 | L19: =SUMIF('قيود اليوميه'!G:G,'ميزان المراجعه'!C19,'قيود اليوميه'!E:E) -> 0 | M19: =IF(I19-J19+K19-L19>0,I19-J19+K19-L19,"") | N19: =IF(J19-I19+L19-K19>0,J19-I19+L19-K19,"") | O19: =IFERROR(IF(N19<>"",N19,M19*-1),"") | P19: الودائع والتامينات طويله الاجل | Q19: اصول غير متداوله
C20: 12 | D20: اصول متداوله | E20: مدين | F20: المركز المالي | G20: 2 | H20: رئيسي
C21: 121 | D21: النقديه وما في حكمها | E21: مدين | F21: المركز المالي | G21: 3 | H21: رئيسي
C22: 121000 | D22: الصندوق الرئيسي | E22: مدين | F22: المركز المالي | G22: 4 | H22: فرعي | K22: =SUMIF('قيود اليوميه'!G:G,'ميزان المراجعه'!C22,'قيود اليوميه'!D:D) -> 0 | L22: =SUMIF('قيود اليوميه'!G:G,'ميزان المراجعه'!C22,'قيود اليوميه'!E:E) -> 0 | M22: =IF(I22-J22+K22-L22>0,I22-J22+K22-L22,"") | N22: =IF(J22-I22+L22-K22>0,J22-I22+L22-K22,"") | O22: =IFERROR(IF(N22<>"",N22,M22*-1),"") | P22: النقديه زما في حكمها | Q22: اصول متداوله
C23: 121001 | D23: الصندوق الفرعي | E23: مدين | F23: المركز المالي | G23: 4 | H23: فرعي | K23: =SUMIF('قيود اليوميه'!G:G,'ميزان المراجعه'!C23,'قيود اليوميه'!D:D) -> 0 | L23: =SUMIF('قيود اليوميه'!G:G,'ميزان المراجعه'!C23,'قيود اليوميه'!E:E) -> 0 | M23: =IF(I23-J23+K23-L23>0,I23-J23+K23-L23,"") | N23: =IF(J23-I23+L23-K23>0,J23-I23+L23-K23,"") | O23: =IFERROR(IF(N23<>"",N23,M23*-1),"") | P23: النقديه زما في حكمها | Q23: اصول متداوله
C24: 121002 | D24: حساب البنك الاهلي | E24: مدين | F24: المركز المالي | G24: 4 | H24: فرعي | K24: =SUMIF('قيود اليوميه'!G:G,'ميزان المراجعه'!C24,'قيود اليوميه'!D:D) -> 851000 | L24: =SUMIF('قيود اليوميه'!G:G,'ميزان المراجعه'!C24,'قيود اليوميه'!E:E) -> 423200 | M24: =IF(I24-J24+K24-L24>0,I24-J24+K24-L24,"") -> 427800 | N24: =IF(J24-I24+L24-K24>0,J24-I24+L24-K24,"") | O24: =IFERROR(IF(N24<>"",N24,M24*-1),"") -> -427800 | P24: النقديه زما في حكمها | Q24: اصول متداوله
C25: 121003 | D25: حساب بنك مصر | E25: مدين | F25: المركز المالي | G25: 4 | H25: فرعي | K25: =SUMIF('قيود اليوميه'!G:G,'ميزان المراجعه'!C25,'قيود اليوميه'!D:D) -> 400000 | L25: =SUMIF('قيود اليوميه'!G:G,'ميزان المراجعه'!C25,'قيود اليوميه'!E:E) -> 11250 | M25: =IF(I25-J25+K25-L25>0,I25-J25+K25-L25,"") -> 388750 | N25: =IF(J25-I25+L25-K25>0,J25-I25+L25-K25,"") | O25: =IFERROR(IF(N25<>"",N25,M25*-1),"") -> -388750 | P25: النقديه زما في حكمها | Q25: اصول متداوله
C26: 121004 | D26: حساب بنك الCIB | E26: مدين | F26: المركز المالي | G26: 4 | H26: فرعي | K26: =SUMIF('قيود اليوميه'!G:G,'ميزان المراجعه'!C26,'قيود اليوميه'!D:D) -> 800000 | L26: =SUMIF('قيود اليوميه'!G:G,'ميزان المراجعه'!C26,'قيود اليوميه'!E:E) -> 95700 | M26: =IF(I26-J26+K26-L26>0,I26-J26+K26-L26,"") -> 704300 | N26: =IF(J26-I26+L26-K26>0,J26-I26+L26-K26,"") | O26: =IFERROR(IF(N26<>"",N26,M26*-1),"") -> -704300 | P26: النقديه زما في حكمها | Q26: اصول متداوله
C27: 121005 | D27: شيكات تحت التحصيل | E27: مدين | F27: المركز المالي | G27: 4 | H27: فرعي | K27: =SUMIF('قيود اليوميه'!G:G,'ميزان المراجعه'!C27,'قيود اليوميه'!D:D) -> 0 | L27: =SUMIF('قيود اليوميه'!G:G,'ميزان المراجعه'!C27,'قيود اليوميه'!E:E) -> 0 | M27: =IF(I27-J27+K27-L27>0,I27-J27+K27-L27,"") | N27: =IF(J27-I27+L27-K27>0,J27-I27+L27-K27,"") | O27: =IFERROR(IF(N27<>"",N27,M27*-1),"") | P27: النقديه زما في حكمها | Q27: اصول متداوله
C28: 122 | D28: العملاء والمدينون | E28: مدين | F28: المركز المالي | G28: 3 | H28: رئيسي
C29: 122000 | D29: العملاء المحليون | E29: مدين | F29: المركز المالي | G29: 4 | H29: فرعي | K29: =SUMIF('قيود اليوميه'!G:G,'ميزان المراجعه'!C29,'قيود اليوميه'!D:D) -> 330000 | L29: =SUMIF('قيود اليوميه'!G:G,'ميزان المراجعه'!C29,'قيود اليوميه'!E:E) -> 50000 | M29: =IF(I29-J29+K29-L29>0,I29-J29+K29-L29,"") -> 280000 | N29: =IF(J29-I29+L29-K29>0,J29-I29+L29-K29,"") | O29: =IFERROR(IF(N29<>"",N29,M29*-1),"") -> -280000 | P29: العملاء والمدينون | Q29: اصول متداوله
C30: 122001 | D30: العملاء الخارجيون | E30: مدين | F30: المركز المالي | G30: 4 | H30: فرعي | K30: =SUMIF('قيود اليوميه'!G:G,'ميزان المراجعه'!C30,'قيود اليوميه'!D:D) -> 0 | L30: =SUMIF('قيود اليوميه'!G:G,'ميزان المراجعه'!C30,'قيود اليوميه'!E:E) -> 0 | M30: =IF(I30-J30+K30-L30>0,I30-J30+K30-L30,"") | N30: =IF(J30-I30+L30-K30>0,J30-I30+L30-K30,"") | O30: =IFERROR(IF(N30<>"",N30,M30*-1),"") | P30: العملاء والمدينون | Q30: اصول متداوله
C31: 123 | D31: المخزون | E31: مدين | F31: المركز المالي | G31: 3 | H31: رئيسي
C32: 123000 | D32: مخزون بضاعه تامه | E32: مدين | F32: المركز المالي | G32: 4 | H32: فرعي | K32: =SUMIF('قيود اليوميه'!G:G,'ميزان المراجعه'!C32,'قيود اليوميه'!D:D) -> 0 | L32: =SUMIF('قيود اليوميه'!G:G,'ميزان المراجعه'!C32,'قيود اليوميه'!E:E) -> 0 | M32: =IF(I32-J32+K32-L32>0,I32-J32+K32-L32,"") | N32: =IF(J32-I32+L32-K32>0,J32-I32+L32-K32,"") | O32: =IFERROR(IF(N32<>"",N32,M32*-1),"") | P32: المخزون | Q32: اصول متداوله
C33: 123001 | D33: مخزون تحت الفحص | E33: مدين | F33: المركز المالي | G33: 4 | H33: فرعي | K33: =SUMIF('قيود اليوميه'!G:G,'ميزان المراجعه'!C33,'قيود اليوميه'!D:D) -> 0 | L33: =SUMIF('قيود اليوميه'!G:G,'ميزان المراجعه'!C33,'قيود اليوميه'!E:E) -> 0 | M33: =IF(I33-J33+K33-L33>0,I33-J33+K33-L33,"") | N33: =IF(J33-I33+L33-K33>0,J33-I33+L33-K33,"") | O33: =IFERROR(IF(N33<>"",N33,M33*-1),"") | P33: المخزون | Q33: اصول متداوله
C34: 124 | D34: المصروفات المقدم | E34: مدين | F34: المركز المالي | G34: 3 | H34: رئيسي
C35: 124000 | D35: ايجار مقدم | E35: مدين | F35: المركز المالي | G35: 4 | H35: فرعي | K35: =SUMIF('قيود اليوميه'!G:G,'ميزان المراجعه'!C35,'قيود اليوميه'!D:D) -> 146250 | L35: =SUMIF('قيود اليوميه'!G:G,'ميزان المراجعه'!C35,'قيود اليوميه'!E:E) -> 11250 | M35: =IF(I35-J35+K35-L35>0,I35-J35+K35-L35,"") -> 135000 | N35: =IF(J35-I35+L35-K35>0,J35-I35+L35-K35,"") | O35: =IFERROR(IF(N35<>"",N35,M35*-1),"") -> -135000 | P35: المخزون | Q35: اصول متداوله
C36: 124001 | D36: تأمينات مقدمه | E36: مدين | F36: المركز المالي | G36: 4 | H36: فرعي | K36: =SUMIF('قيود اليوميه'!G:G,'ميزان المراجعه'!C36,'قيود اليوميه'!D:D) -> 0 | L36: =SUMIF('قيود اليوميه'!G:G,'ميزان المراجعه'!C36,'قيود اليوميه'!E:E) -> 0 | M36: =IF(I36-J36+K36-L36>0,I36-J36+K36-L36,"") | N36: =IF(J36-I36+L36-K36>0,J36-I36+L36-K36,"") | O36: =IFERROR(IF(N36<>"",N36,M36*-1),"") | P36: المخزون | Q36: اصول متداوله
C37: 125 | D37: ارصده مدينه اخري | E37: مدين | F37: المركز المالي | G37: 3 | H37: رئيسي
C38: 125000 | D38: ضريبه القيمه المضافه للمدخلات | E38: مدين | F38: المركز المالي | G38: 4 | H38: فرعي | K38: =SUMIF('قيود اليوميه'!G:G,'ميزان المراجعه'!C38,'قيود اليوميه'!D:D) -> 15000 | L38: =SUMIF('قيود اليوميه'!G:G,'ميزان المراجعه'!C38,'قيود اليوميه'!E:E) -> 15000 | M38: =IF(I38-J38+K38-L38>0,I38-J38+K38-L38,"") | N38: =IF(J38-I38+L38-K38>0,J38-I38+L38-K38,"") | O38: =IFERROR(IF(N38<>"",N38,M38*-1),"") | P38: ارصده مدينه اخري | Q38: اصول متداوله
C39: 125001 | D39: السلف المؤقته | E39: مدين | F39: المركز المالي | G39: 4 | H39: فرعي | K39: =SUMIF('قيود اليوميه'!G:G,'ميزان المراجعه'!C39,'قيود اليوميه'!D:D) -> 5000 | L39: =SUMIF('قيود اليوميه'!G:G,'ميزان المراجعه'!C39,'قيود اليوميه'!E:E) -> 1000 | M39: =IF(I39-J39+K39-L39>0,I39-J39+K39-L39,"") -> 4000 | N39: =IF(J39-I39+L39-K39>0,J39-I39+L39-K39,"") | O39: =IFERROR(IF(N39<>"",N39,M39*-1),"") -> -4000 | P39: ارصده مدينه اخري | Q39: اصول متداوله
C40: 125002 | D40: العهد تحت التسويه | E40: مدين | F40: المركز المالي | G40: 4 | H40: فرعي | K40: =SUMIF('قيود اليوميه'!G:G,'ميزان المراجعه'!C40,'قيود اليوميه'!D:D) -> 0 | L40: =SUMIF('قيود اليوميه'!G:G,'ميزان المراجعه'!C40,'قيود اليوميه'!E:E) -> 0 | M40: =IF(I40-J40+K40-L40>0,I40-J40+K40-L40,"") | N40: =IF(J40-I40+L40-K40>0,J40-I40+L40-K40,"") | O40: =IFERROR(IF(N40<>"",N40,M40*-1),"") | P40: ارصده مدينه اخري | Q40: اصول متداوله
C41: 125003 | D41: دفعات مقدمه للموردين | E41: مدين | F41: المركز المالي | G41: 4 | H41: فرعي | K41: =SUMIF('قيود اليوميه'!G:G,'ميزان المراجعه'!C41,'قيود اليوميه'!D:D) -> 0 | L41: =SUMIF('قيود اليوميه'!G:G,'ميزان المراجعه'!C41,'قيود اليوميه'!E:E) -> 0 | M41: =IF(I41-J41+K41-L41>0,I41-J41+K41-L41,"") | N41: =IF(J41-I41+L41-K41>0,J41-I41+L41-K41,"") | O41: =IFERROR(IF(N41<>"",N41,M41*-1),"") | P41: ارصده مدينه اخري | Q41: اصول متداوله
C42: 126 | D42: المستحق من الشركاء | E42: مدين | F42: المركز المالي | G42: 3 | H42: رئيسي
C43: 126000 | D43: المستحق من الشريك عبدالله | E43: مدين | F43: المركز المالي | G43: 4 | H43: فرعي | K43: =SUMIF('قيود اليوميه'!G:G,'ميزان المراجعه'!C43,'قيود اليوميه'!D:D) -> 0 | L43: =SUMIF('قيود اليوميه'!G:G,'ميزان المراجعه'!C43,'قيود اليوميه'!E:E) -> 0 | M43: =IF(I43-J43+K43-L43>0,I43-J43+K43-L43,"") | N43: =IF(J43-I43+L43-K43>0,J43-I43+L43-K43,"") | O43: =IFERROR(IF(N43<>"",N43,M43*-1),"") | P43: المستحق من الشركاء | Q43: اصول متداوله
...

Sheet قيود اليوميه
B1: قيود اليوميه لعام 2025
B3: التاريخ | C3: رقم القيد | D3: مدين | E3: دائن | F3: رصيد | G3: رقم احساب | H3: اسم الحساب | I3: الوصف | J3: رقم الجهه | K3: اسم الجهه | L3: نوع الجهه
B4: 45658 | C4: 1 | E4: 2000000 | F4: =D4-E4 -> -2000000 | G4: 211000 | H4: =IF(G4<>"",VLOOKUP(G4,'ميزان المراجعه'!$C$6:$D$167,2,FALSE),"") -> راس المال | I4: اثبات راس مال الشركه | K4: =IF(J4<>"",VLOOKUP(J4,الجهات!$B$4:$D$23,2),"") | L4: =IF(J4<>"",VLOOKUP(J4,الجهات!$B$4:$D$23,3),"")
B5: 45658 | C5: 1 | D5: 800000 | F5: =F4+D5-E5 -> -1200000 | G5: 235000 | H5: =IF(G5<>"",VLOOKUP(G5,'ميزان المراجعه'!$C$6:$D$167,2,FALSE),"") -> المستحق الي الشريك عبدالله | I5: اثبات راس مال الشركه | K5: =IF(J5<>"",VLOOKUP(J5,الجهات!$B$4:$D$23,2),"") | L5: =IF(J5<>"",VLOOKUP(J5,الجهات!$B$4:$D$23,3),"")
B6: 45658 | C6: 1 | D6: 800000 | F6: =F5+D6-E6 -> -400000 | G6: 235001 | H6: =IF(G6<>"",VLOOKUP(G6,'ميزان المراجعه'!$C$6:$D$167,2,FALSE),"") -> المستحق الي الشريك محمد | I6: اثبات راس مال الشركه | K6: =IF(J6<>"",VLOOKUP(J6,الجهات!$B$4:$D$23,2),"") | L6: =IF(J6<>"",VLOOKUP(J6,الجهات!$B$4:$D$23,3),"")
B7: 45658 | C7: 1 | D7: 400000 | F7: =F6+D7-E7 -> 0 | G7: 235002 | H7: =IF(G7<>"",VLOOKUP(G7,'ميزان المراجعه'!$C$6:$D$167,2,FALSE),"") -> المستحق الي الشريك خالد | I7: اثبات راس مال الشركه | K7: =IF(J7<>"",VLOOKUP(J7,الجهات!$B$4:$D$23,2),"") | L7: =IF(J7<>"",VLOOKUP(J7,الجهات!$B$4:$D$23,3),"")
F8: =F7+D8-E8 -> 0 | H8: =IF(G8<>"",VLOOKUP(G8,'ميزان المراجعه'!$C$6:$D$167,2,FALSE),"") | K8: =IF(J8<>"",VLOOKUP(J8,الجهات!$B$4:$D$23,2),"") | L8: =IF(J8<>"",VLOOKUP(J8,الجهات!$B$4:$D$23,3),"")
F9: =F8+D9-E9 -> 0 | H9: =IF(G9<>"",VLOOKUP(G9,'ميزان المراجعه'!$C$6:$D$167,2,FALSE),"") | K9: =IF(J9<>"",VLOOKUP(J9,الجهات!$B$4:$D$23,2),"") | L9: =IF(J9<>"",VLOOKUP(J9,الجهات!$B$4:$D$23,3),"")
C10: 2 | D10: 800000 | F10: =F9+D10-E10 -> 800000 | G10: 121004 | H10: =IF(G10<>"",VLOOKUP(G10,'ميزان المراجعه'!$C$6:$D$167,2,FALSE),"") -> حساب بنك الCIB | K10: =IF(J10<>"",VLOOKUP(J10,الجهات!$B$4:$D$23,2),"") | L10: =IF(J10<>"",VLOOKUP(J10,الجهات!$B$4:$D$23,3),"")
C11: 2 | D11: 400000 | F11: =F10+D11-E11 -> 1200000 | G11: 121003 | H11: =IF(G11<>"",VLOOKUP(G11,'ميزان المراجعه'!$C$6:$D$167,2,FALSE),"") -> حساب بنك مصر | K11: =IF(J11<>"",VLOOKUP(J11,الجهات!$B$4:$D$23,2),"") | L11: =IF(J11<>"",VLOOKUP(J11,الجهات!$B$4:$D$23,3),"")
B12: 45779 | C12: 2 | D12: 800000 | F12: =F11+D12-E12 -> 2000000 | G12: 121002 | H12: =IF(G12<>"",VLOOKUP(G12,'ميزان المراجعه'!$C$6:$D$167,2,FALSE),"") -> حساب البنك الاهلي | I12: ايداع راس مال الشركه | K12: =IF(J12<>"",VLOOKUP(J12,الجهات!$B$4:$D$23,2),"") | L12: =IF(J12<>"",VLOOKUP(J12,الجهات!$B$4:$D$23,3),"")
B13: 45779 | C13: 2 | E13: 800000 | F13: =F12+D13-E13 -> 1200000 | G13: 235000 | H13: =IF(G13<>"",VLOOKUP(G13,'ميزان المراجعه'!$C$6:$D$167,2,FALSE),"") -> المستحق الي الشريك عبدالله | I13: ايداع راس مال الشركه | K13: =IF(J13<>"",VLOOKUP(J13,الجهات!$B$4:$D$23,2),"") | L13: =IF(J13<>"",VLOOKUP(J13,الجهات!$B$4:$D$23,3),"")
B14: 45779 | C14: 2 | E14: 800000 | F14: =F13+D14-E14 -> 400000 | G14: 235001 | H14: =IF(G14<>"",VLOOKUP(G14,'ميزان المراجعه'!$C$6:$D$167,2,FALSE),"") -> المستحق الي الشريك محمد | I14: ايداع راس مال الشركه | K14: =IF(J14<>"",VLOOKUP(J14,الجهات!$B$4:$D$23,2),"") | L14: =IF(J14<>"",VLOOKUP(J14,الجهات!$B$4:$D$23,3),"")
B15: 45779 | C15: 2 | E15: 400000 | F15: =F14+D15-E15 -> 0 | G15: 235002 | H15: =IF(G15<>"",VLOOKUP(G15,'ميزان المراجعه'!$C$6:$D$167,2,FALSE),"") -> المستحق الي الشريك خالد | I15: ايداع راس مال الشركه | K15: =IF(J15<>"",VLOOKUP(J15,الجهات!$B$4:$D$23,2),"") | L15: =IF(J15<>"",VLOOKUP(J15,الجهات!$B$4:$D$23,3),"")
F16: =F15+D16-E16 -> 0 | H16: =IF(G16<>"",VLOOKUP(G16,'ميزان المراجعه'!$C$6:$D$167,2,FALSE),"") | K16: =IF(J16<>"",VLOOKUP(J16,الجهات!$B$4:$D$23,2),"") | L16: =IF(J16<>"",VLOOKUP(J16,الجهات!$B$4:$D$23,3),"")
B17: 45933 | C17: 3 | D17: 60000 | F17: =F16+D17-E17 -> 60000 | G17: 124000 | H17: =IF(G17<>"",VLOOKUP(G17,'ميزان المراجعه'!$C$6:$D$167,2,FALSE),"") -> ايجار مقدم | I17: سداد ايجار المستودع | K17: =IF(J17<>"",VLOOKUP(J17,الجهات!$B$4:$D$23,2),"") | L17: =IF(J17<>"",VLOOKUP(J17,الجهات!$B$4:$D$23,3),"")
B18: 45933 | C18: 3 | D18: 5000 | F18: =F17+D18-E18 -> 65000 | G18: 431002 | H18: =IF(G18<>"",VLOOKUP(G18,'ميزان المراجعه'!$C$6:$D$167,2,FALSE),"") -> مصاريف بنكيه | I18: سداد ايجار المستودع | K18: =IF(J18<>"",VLOOKUP(J18,الجهات!$B$4:$D$23,2),"") | L18: =IF(J18<>"",VLOOKUP(J18,الجهات!$B$4:$D$23,3),"")
B19: 45933 | C19: 3 | E19: 60000 | F19: =F18+D19-E19 -> 5000 | G19: 121002 | H19: =IF(G19<>"",VLOOKUP(G19,'ميزان المراجعه'!$C$6:$D$167,2,FALSE),"") -> حساب البنك الاهلي | I19: سداد ايجار المستودع | K19: =IF(J19<>"",VLOOKUP(J19,الجهات!$B$4:$D$23,2),"") | L19: =IF(J19<>"",VLOOKUP(J19,الجهات!$B$4:$D$23,3),"")
B20: 45933 | C20: 3 | E20: 5000 | F20: =F19+D20-E20 -> 0 | G20: 121002 | H20: =IF(G20<>"",VLOOKUP(G20,'ميزان المراجعه'!$C$6:$D$167,2,FALSE),"") -> حساب البنك الاهلي | I20: سداد ايجار المستودع | K20: =IF(J20<>"",VLOOKUP(J20,الجهات!$B$4:$D$23,2),"") | L20: =IF(J20<>"",VLOOKUP(J20,الجهات!$B$4:$D$23,3),"")
F21: =F20+D21-E21 -> 0 | H21: =IF(G21<>"",VLOOKUP(G21,'ميزان المراجعه'!$C$6:$D$167,2,FALSE),"") | K21: =IF(J21<>"",VLOOKUP(J21,الجهات!$B$4:$D$23,2),"") | L21: =IF(J21<>"",VLOOKUP(J21,الجهات!$B$4:$D$23,3),"")
B22: 15/4/2025 | C22: 4 | D22: 75000 | F22: =F21+D22-E22 -> 75000 | G22: 124000 | H22: =IF(G22<>"",VLOOKUP(G22,'ميزان المراجعه'!$C$6:$D$167,2,FALSE),"") -> ايجار مقدم | I22: سداد ايجار معدات | K22: =IF(J22<>"",VLOOKUP(J22,الجهات!$B$4:$D$23,2),"") | L22: =IF(J22<>"",VLOOKUP(J22,الجهات!$B$4:$D$23,3),"")
B23: 15/4/2025 | C23: 4 | D23: 700 | F23: =F22+D23-E23 -> 75700 | G23: 431002 | H23: =IF(G23<>"",VLOOKUP(G23,'ميزان المراجعه'!$C$6:$D$167,2,FALSE),"") -> مصاريف بنكيه | I23: سداد ايجار معدات | K23: =IF(J23<>"",VLOOKUP(J23,الجهات!$B$4:$D$23,2),"") | L23: =IF(J23<>"",VLOOKUP(J23,الجهات!$B$4:$D$23,3),"")
B24: 15/4/2025 | C24: 4 | E24: 75000 | F24: =F23+D24-E24 -> 700 | G24: 121004 | H24: =IF(G24<>"",VLOOKUP(G24,'ميزان المراجعه'!$C$6:$D$167,2,FALSE),"") -> حساب بنك الCIB | I24: سداد ايجار معدات | K24: =IF(J24<>"",VLOOKUP(J24,الجهات!$B$4:$D$23,2),"") | L24: =IF(J24<>"",VLOOKUP(J24,الجهات!$B$4:$D$23,3),"")
B25: 15/4/2025 | C25: 4 | E25: 700 | F25: =F24+D25-E25 -> 0 | G25: 121004 | H25: =IF(G25<>"",VLOOKUP(G25,'ميزان المراجعه'!$C$6:$D$167,2,FALSE),"") -> حساب بنك الCIB | I25: سداد ايجار معدات | K25: =IF(J25<>"",VLOOKUP(J25,الجهات!$B$4:$D$23,2),"") | L25: =IF(J25<>"",VLOOKUP(J25,الجهات!$B$4:$D$23,3),"")
F26: =F25+D26-E26 -> 0 | H26: =IF(G26<>"",VLOOKUP(G26,'ميزان المراجعه'!$C$6:$D$167,2,FALSE),"") | K26: =IF(J26<>"",VLOOKUP(J26,الجهات!$B$4:$D$23,2),"") | L26: =IF(J26<>"",VLOOKUP(J26,الجهات!$B$4:$D$23,3),"")
B27: 31/5/2025 | C27: 5 | D27: 11250 | F27: =F26+D27-E27 -> 11250 | G27: 124000 | H27: =IF(G27<>"",VLOOKUP(G27,'ميزان المراجعه'!$C$6:$D$167,2,FALSE),"") -> ايجار مقدم | I27: استحقاق مايو من الاجارات
B28: 31/5/2025 | C28: 5 | E28: 11250 | F28: =F27+D28-E28 -> 0 | G28: 121003 | H28: =IF(G28<>"",VLOOKUP(G28,'ميزان المراجعه'!$C$6:$D$167,2,FALSE),"") -> حساب بنك مصر | I28: استحقاق مايو من الاجارات
F29: =F28+D29-E29 -> 0 | H29: =IF(G29<>"",VLOOKUP(G29,'ميزان المراجعه'!$C$6:$D$167,2,FALSE),"")
F30: =F29+D30-E30 -> 0 | H30: =IF(G30<>"",VLOOKUP(G30,'ميزان المراجعه'!$C$6:$D$167,2,FALSE),"")
B31: 31/5/2025 | C31: 6 | D31: 11250 | F31: =F26+D31-E31 -> 11250 | G31: 422001 | H31: =IF(G31<>"",VLOOKUP(G31,'ميزان المراجعه'!$C$6:$D$167,2,FALSE),"") -> مصروف ايجار | I31: اقفال ما يخص مايو من الايجار المدفوع مقدما | K31: =IF(J31<>"",VLOOKUP(J31,الجهات!$B$4:$D$23,2),"") | L31: =IF(J31<>"",VLOOKUP(J31,الجهات!$B$4:$D$23,3),"")
B32: 31/5/2026 | C32: 6 | E32: 11250 | F32: =F31+D32-E32 -> 0 | G32: 124000 | H32: =IF(G32<>"",VLOOKUP(G32,'ميزان المراجعه'!$C$6:$D$167,2,FALSE),"") -> ايجار مقدم | I32: اقفال ما يخص مايو من الايجار المدفوع مقدما | K32: =IF(J32<>"",VLOOKUP(J32,الجهات!$B$4:$D$23,2),"") | L32: =IF(J32<>"",VLOOKUP(J32,الجهات!$B$4:$D$23,3),"")
F33: =F32+D33-E33 -> 0 | H33: =IF(G33<>"",VLOOKUP(G33,'ميزان المراجعه'!$C$6:$D$167,2,FALSE),"") | K33: =IF(J33<>"",VLOOKUP(J33,الجهات!$B$4:$D$23,2),"") | L33: =IF(J33<>"",VLOOKUP(J33,الجهات!$B$4:$D$23,3),"")
B34: 45694 | F34: =F33+D34-E34 -> 0 | H34: =IF(G34<>"",VLOOKUP(G34,'ميزان المراجعه'!$C$6:$D$167,2,FALSE),"") | K34: =IF(J34<>"",VLOOKUP(J34,الجهات!$B$4:$D$23,2),"") | L34: =IF(J34<>"",VLOOKUP(J34,الجهات!$B$4:$D$23,3),"")
B35: 45694 | C35: 7 | D35: 100000 | F35: =F34+D35-E35 -> 100000 | G35: 111003 | H35: =IF(G35<>"",VLOOKUP(G35,'ميزان المراجعه'!$C$6:$D$167,2,FALSE),"") -> السيارات | I35: شراء سيارات | K35: =IF(J35<>"",VLOOKUP(J35,الجهات!$B$4:$D$23,2),"") | L35: =IF(J35<>"",VLOOKUP(J35,الجهات!$B$4:$D$23,3),"")
B36: 45694 | C36: 7 | D36: 1000 | F36: =F35+D36-E36 -> 101000 | G36: 431002 | H36: =IF(G36<>"",VLOOKUP(G36,'ميزان المراجعه'!$C$6:$D$167,2,FALSE),"") -> مصاريف بنكيه | I36: شراء سيارات | K36: =IF(J36<>"",VLOOKUP(J36,الجهات!$B$4:$D$23,2),"") | L36: =IF(J36<>"",VLOOKUP(J36,الجهات!$B$4:$D$23,3),"")
B37: 45694 | C37: 7 | E37: 100000 | F37: =F36+D37-E37 -> 1000 | G37: 121002 | H37: =IF(G37<>"",VLOOKUP(G37,'ميزان المراجعه'!$C$6:$D$167,2,FALSE),"") -> حساب البنك الاهلي | I37: شراء سيارات | K37: =IF(J37<>"",VLOOKUP(J37,الجهات!$B$4:$D$23,2),"") | L37: =IF(J37<>"",VLOOKUP(J37,الجهات!$B$4:$D$23,3),"")
C38: 7 | E38: 1000 | F38: =F37+D38-E38 -> 0 | G38: 121002 | H38: =IF(G38<>"",VLOOKUP(G38,'ميزان المراجعه'!$C$6:$D$167,2,FALSE),"") -> حساب البنك الاهلي | I38: شراء سيارات | K38: =IF(J38<>"",VLOOKUP(J38,الجهات!$B$4:$D$23,2),"") | L38: =IF(J38<>"",VLOOKUP(J38,الجهات!$B$4:$D$23,3),"")
F39: =F38+D39-E39 -> 0 | H39: =IF(G39<>"",VLOOKUP(G39,'ميزان المراجعه'!$C$6:$D$167,2,FALSE),"") | K39: =IF(J39<>"",VLOOKUP(J39,الجهات!$B$4:$D$23,2),"") | L39: =IF(J39<>"",VLOOKUP(J39,الجهات!$B$4:$D$23,3),"")
B40: 45697 | C40: 8 | D40: 50000 | F40: =F39+D40-E40 -> 50000 | G40: 111004 | H40: =IF(G40<>"",VLOOKUP(G40,'ميزان المراجعه'!$C$6:$D$167,2,FALSE),"") -> اجهزه الحاسب | I40: شراء اجهزه حاسب | K40: =IF(J40<>"",VLOOKUP(J40,الجهات!$B$4:$D$23,2),"") | L40: =IF(J40<>"",VLOOKUP(J40,الجهات!$B$4:$D$23,3),"")
B41: 45697 | C41: 8 | D41: 500 | F41: =F40+D41-E41 -> 50500 | G41: 431002 | H41: =IF(G41<>"",VLOOKUP(G41,'ميزان المراجعه'!$C$6:$D$167,2,FALSE),"") -> مصاريف بنكيه | I41: شراء اجهزه حاسب | K41: =IF(J41<>"",VLOOKUP(J41,الجهات!$B$4:$D$23,2),"") | L41: =IF(J41<>"",VLOOKUP(J41,الجهات!$B$4:$D$23,3),"")
...

Sheet الجهات
B3: رقم الجهه | C3: اسم الجهه | D3: نوع الجهه | E3: رصيد اول المده | G3: حركه الفتره | I3: رصيد اخر المده
E4: مدين | F4: دائن | G4: مدين | H4: دائن | I4: مدين | J4: دائن
B5: 1001 | C5: مورد 1 | D5: مورد | G5: =SUMIF('قيود اليوميه'!J:J,الجهات!B5,'قيود اليوميه'!D:D) -> 100000 | H5: =SUMIF('قيود اليوميه'!J:J,الجهات!B5,'قيود اليوميه'!E:E) -> 165000 | I5: =IF(E5-F5+G5-H5>0,E5-F5+G5-H5,"") | J5: =IF(F5-E5+H5-G5>0,F5-E5+H5-G5,"") -> 65000
B6: 1002 | C6: مورد2 | D6: مورد | G6: =SUMIF('قيود اليوميه'!J:J,الجهات!B6,'قيود اليوميه'!D:D) -> 0 | H6: =SUMIF('قيود اليوميه'!J:J,الجهات!B6,'قيود اليوميه'!E:E) -> 0 | I6: =IF(E6-F6+G6-H6>0,E6-F6+G6-H6,"") | J6: =IF(F6-E6+H6-G6>0,F6-E6+H6-G6,"")
B7: 1003 | C7: مورد3 | D7: مورد | G7: =SUMIF('قيود اليوميه'!J:J,الجهات!B7,'قيود اليوميه'!D:D) -> 0 | H7: =SUMIF('قيود اليوميه'!J:J,الجهات!B7,'قيود اليوميه'!E:E) -> 0 | I7: =IF(E7-F7+G7-H7>0,E7-F7+G7-H7,"") | J7: =IF(F7-E7+H7-G7>0,F7-E7+H7-G7,"")
B8: 2001 | C8: عميل 1 | D8: عميل | G8: =SUMIF('قيود اليوميه'!J:J,الجهات!B8,'قيود اليوميه'!D:D) -> 0 | H8: =SUMIF('قيود اليوميه'!J:J,الجهات!B8,'قيود اليوميه'!E:E) -> 0 | I8: =IF(E8-F8+G8-H8>0,E8-F8+G8-H8,"") | J8: =IF(F8-E8+H8-G8>0,F8-E8+H8-G8,"")
B9: 2002 | C9: عميل 2 | D9: عميل | G9: =SUMIF('قيود اليوميه'!J:J,الجهات!B9,'قيود اليوميه'!D:D) -> 330000 | H9: =SUMIF('قيود اليوميه'!J:J,الجهات!B9,'قيود اليوميه'!E:E) -> 50000 | I9: =IF(E9-F9+G9-H9>0,E9-F9+G9-H9,"") -> 280000 | J9: =IF(F9-E9+H9-G9>0,F9-E9+H9-G9,"")
B10: 2003 | C10: عميل 3 | D10: عميل | G10: =SUMIF('قيود اليوميه'!J:J,الجهات!B10,'قيود اليوميه'!D:D) -> 0 | H10: =SUMIF('قيود اليوميه'!J:J,الجهات!B10,'قيود اليوميه'!E:E) -> 0 | I10: =IF(E10-F10+G10-H10>0,E10-F10+G10-H10,"") | J10: =IF(F10-E10+H10-G10>0,F10-E10+H10-G10,"")
B11: 3001 | C11: احمد علي | D11: موظف | G11: =SUMIF('قيود اليوميه'!J:J,الجهات!B11,'قيود اليوميه'!D:D) -> 5000 | H11: =SUMIF('قيود اليوميه'!J:J,الجهات!B11,'قيود اليوميه'!E:E) -> 1000 | I11: =IF(E11-F11+G11-H11>0,E11-F11+G11-H11,"") -> 4000 | J11: =IF(F11-E11+H11-G11>0,F11-E11+H11-G11,"")
B12: 3002 | C12: محمود علي | D12: موظف | G12: =SUMIF('قيود اليوميه'!J:J,الجهات!B12,'قيود اليوميه'!D:D) -> 0 | H12: =SUMIF('قيود اليوميه'!J:J,الجهات!B12,'قيود اليوميه'!E:E) -> 0 | I12: =IF(E12-F12+G12-H12>0,E12-F12+G12-H12,"") | J12: =IF(F12-E12+H12-G12>0,F12-E12+H12-G12,"")
B13: الاجمالي | E13: =SUBTOTAL(9,E5:E12) -> 0 | F13: =SUBTOTAL(9,F5:F12) -> 0 | G13: =SUBTOTAL(9,G5:G12) -> 435000 | H13: =SUBTOTAL(9,H5:H12) -> 216000 | I13: =SUBTOTAL(9,I5:I12) -> 284000 | J13: =SUBTOTAL(9,J5:J12) -> 65000

Sheet قائمه الدخل
C3: قائمه الدخل عن عام 2025
C5: التبويب | D5: 2025
C6: ايرادات النشاط الرئيسي | D6: =SUMIF('ميزان المراجعه'!$Q:$Q,'قائمه الدخل'!C6,'ميزان المراجعه'!O:O) -> 300000
C7: تكلفه البضاعه المباعه | D7: =SUMIF('ميزان المراجعه'!$Q:$Q,'قائمه الدخل'!C7,'ميزان المراجعه'!O:O) -> -150000
C8: مجمل الربح | D8: =SUM(D6:D7) -> 150000 | E8: =D8/$D$6 -> 0.5
C9: مصروفات التشغيل | D9: =SUMIF('ميزان المراجعه'!$Q:$Q,'قائمه الدخل'!C9,'ميزان المراجعه'!O:O) -> -47500
C10: الربح التشغيلي | D10: =SUM(D8:D9) -> 102500 | E10: =D10/$D$6 -> 0.34166667
C11: مصروفات اخري | D11: =SUMIF('ميزان المراجعه'!$Q:$Q,'قائمه الدخل'!C11,'ميزان المراجعه'!O:O) -> 0
C12: مصروفات ماليه | D12: =SUMIF('ميزان المراجعه'!$Q:$Q,'قائمه الدخل'!C12,'ميزان المراجعه'!O:O) -> -8900
C13: ايرادات اخري | D13: =SUMIF('ميزان المراجعه'!$Q:$Q,'قائمه الدخل'!C13,'ميزان المراجعه'!O:O) -> 0
C14: الربح قبل االضريبه | D14: =SUM(D10:D13) -> 93600 | E14: =D14/$D$6 -> 0.312
C15: مصروف ضرائب | D15: =SUMIF('ميزان المراجعه'!$Q:$Q,'قائمه الدخل'!C15,'ميزان المراجعه'!O:O) -> -20000
C16: صافي الربح | D16: =SUM(D14:D15) -> 73600 | E16: =D16/$D$6 -> 0.24533333

Sheet قائمه المركز المالي
B3: قائمه المركز المالي عن عام 2025
C5: اصول غير متداوله | D5: 2025 عام
C6: الاصول الثابته | D6: =SUMIF('ميزان المراجعه'!$P:$P,'قائمه المركز المالي'!C6,'ميزان المراجعه'!$O:$O)*-1 -> 208750
C7: الاستثمارات طويله الاجل | D7: =SUMIF('ميزان المراجعه'!$P:$P,'قائمه المركز المالي'!C7,'ميزان المراجعه'!$O:$O)*-1 -> 0
C8: الودائع والتامينات طويله الاجل | D8: =SUMIF('ميزان المراجعه'!$P:$P,'قائمه المركز المالي'!C8,'ميزان المراجعه'!$O:$O)*-1 -> 0
C9: اجمالي الاصول غير المتداوله | D9: =SUM(D6:D8) -> 208750
C10: اصول متداوله
C11: النقديه زما في حكمها | D11: =SUMIF('ميزان المراجعه'!$P:$P,'قائمه المركز المالي'!C11,'ميزان المراجعه'!$O:$O)*-1 -> 1520850
C12: العملاء والمدينون | D12: =SUMIF('ميزان المراجعه'!$P:$P,'قائمه المركز المالي'!C12,'ميزان المراجعه'!$O:$O)*-1 -> 280000
C13: المخزون | D13: =SUMIF('ميزان المراجعه'!$P:$P,'قائمه المركز المالي'!C13,'ميزان المراجعه'!$O:$O)*-1 -> 135000
C14: ارصده مدينه اخري | D14: =SUMIF('ميزان المراجعه'!$P:$P,'قائمه المركز المالي'!C14,'ميزان المراجعه'!$O:$O)*-1 -> 4000
C15: اجمالي الاصول المتداوله | D15: =SUM(D11:D14) -> 1939850
C16: اجمالي الاصول | D16: =D15+D9 -> 2148600
C17: حقوق الملكيه
C18: راس المال | D18: =SUMIF('ميزان المراجعه'!$P:$P,'قائمه المركز المالي'!C18,'ميزان المراجعه'!$O:$O) -> 2000000
C19: الاحتياطيات
C20: ارباح مبقاه | D20: ='قائمه الدخل'!D16 -> 73600
C21: اجمالي حقوق الملكيه | D21: =SUM(D17:D20) -> 2073600
C22: التزامات غير متداوله
C23: القروض طويله الاجل | D23: =SUMIF('ميزان المراجعه'!$P:$P,'قائمه المركز المالي'!C23,'ميزان المراجعه'!$O:$O) -> 0
C24: التزامات للموظفين | D24: =SUMIF('ميزان المراجعه'!$P:$P,'قائمه المركز المالي'!C24,'ميزان المراجعه'!$O:$O) -> 0
C25: التزامات ضمان | D25: =SUMIF('ميزان المراجعه'!$P:$P,'قائمه المركز المالي'!C25,'ميزان المراجعه'!$O:$O) -> 0
C26: التزامات طويله الاجل اخري | D26: =SUMIF('ميزان المراجعه'!$P:$P,'قائمه المركز المالي'!C26,'ميزان المراجعه'!$O:$O) -> 0
C27: اجمالي التزامات غير متداوله | D27: =SUM(D22:D26) -> 0
C28: التزامات متداوله
C29: الدائنون والموردون | D29: =SUMIF('ميزان المراجعه'!$P:$P,'قائمه المركز المالي'!C29,'ميزان المراجعه'!$O:$O) -> 65000
C30: المصروفات المستحقه | D30: =SUMIF('ميزان المراجعه'!$P:$P,'قائمه المركز المالي'!C30,'ميزان المراجعه'!$O:$O) -> 0
C31: الضرائب والرسوم المستحقه | D31: =SUMIF('ميزان المراجعه'!$P:$P,'قائمه المركز المالي'!C31,'ميزان المراجعه'!$O:$O) -> 10000
C32: ارصده دائنه اخري | D32: =SUMIF('ميزان المراجعه'!$P:$P,'قائمه المركز المالي'!C32,'ميزان المراجعه'!$O:$O) -> 0
C33: المستحق الي الشركاء | D33: =SUMIF('ميزان المراجعه'!$P:$P,'قائمه المركز المالي'!C33,'ميزان المراجعه'!$O:$O) -> 0
C34: اجمالي التزامات متداوله | D34: =SUM(D29:D33) -> 75000
C35: اجمالي الالتزامات وحقوق الملكيه | D35: =D34+D27+D21 -> 2148600

Sheet الحركات علي المخزون
B4: رقم العمليه | C4: نوع العمليه | D4: التاريخ | E4: الشهر | F4: كود الصنف | G4: اسم الصنف | H4: وحده القياس | I4: اول المده | J4: وارد | K4: صادر | L4: الرصيد | M4: السعر للوحده | N4: القيمه الاجماليه | O4: تكلفه الوحده | P4: كود المورد | Q4: اسم المورد | R4: رقم الفاتوره | S4: كود العميل | T4: اسم العميل
B5: 10001 | C5: سند ادخال | D5: 45667 | E5: =IF(D5<>"",TEXT(D5,"mmmm"),"") -> January | F5: 10001 | G5: =IF(F5<>"",VLOOKUP(F5,'العملاءوالموردون والاصناف'!$D$3:$F$6,2,FALSE),"") -> صنف1 | H5: =IF(F5<>"",VLOOKUP(F5,'العملاءوالموردون والاصناف'!$D$3:$F$6,3,FALSE),"") -> متر | I5: 0 | J5: 150 | K5: 0 | L5: =I5+J5-K5 -> 150 | M5: 300 | N5: =M5*L5 -> 45000 | O5: =IFERROR(N5/L5,"") -> 300 | P5: 20002 | Q5: =IF(P5<>"",VLOOKUP(P5,'العملاءوالموردون والاصناف'!$I$3:$J$6,2,FALSE),"") -> المورد رقم1
B6: 10002 | C6: سند ادخال | D6: 45698 | E6: =IF(D6<>"",TEXT(D6,"mmmm"),"") -> February | F6: 10001 | G6: =IF(F6<>"",VLOOKUP(F6,'العملاءوالموردون والاصناف'!$D$3:$F$6,2,FALSE),"") -> صنف1 | H6: =IF(F6<>"",VLOOKUP(F6,'العملاءوالموردون والاصناف'!$D$3:$F$6,3,FALSE),"") -> متر | I6: 0 | J6: 100 | K6: 0 | L6: =I6+J6-K6 -> 100 | M6: 300 | N6: =M6*L6 -> 30000 | O6: =IFERROR(N6/L6,"") -> 300 | P6: 20002 | Q6: =IF(P6<>"",VLOOKUP(P6,'العملاءوالموردون والاصناف'!$I$3:$J$6,2,FALSE),"") -> المورد رقم1 | T6: =IF(S6<>"",VLOOKUP(S6,'العملاءوالموردون والاصناف'!$M$3:$N$6,2,FALSE),"")
B7: 10003 | C7: سند ادخال | D7: 45726 | E7: =IF(D7<>"",TEXT(D7,"mmmm"),"") -> March | F7: 10002 | G7: =IF(F7<>"",VLOOKUP(F7,'العملاءوالموردون والاصناف'!$D$3:$F$6,2,FALSE),"") -> صنف2 | H7: =IF(F7<>"",VLOOKUP(F7,'العملاءوالموردون والاصناف'!$D$3:$F$6,3,FALSE),"") -> كيلو | I7: 0 | J7: 100 | K7: 0 | L7: =I7+J7-K7 -> 100 | M7: 250 | N7: =M7*L7 -> 25000 | O7: =IFERROR(N7/L7,"") -> 250 | P7: 20003 | Q7: =IF(P7<>"",VLOOKUP(P7,'العملاءوالموردون والاصناف'!$I$3:$J$6,2,FALSE),"") -> المورد رقم2 | T7: =IF(S7<>"",VLOOKUP(S7,'العملاءوالموردون والاصناف'!$M$3:$N$6,2,FALSE),"")
B8: 10004 | C8: سند ادخال | D8: 45727 | E8: =IF(D8<>"",TEXT(D8,"mmmm"),"") -> March | F8: 10003 | G8: =IF(F8<>"",VLOOKUP(F8,'العملاءوالموردون والاصناف'!$D$3:$F$6,2,FALSE),"") -> صنف3 | H8: =IF(F8<>"",VLOOKUP(F8,'العملاءوالموردون والاصناف'!$D$3:$F$6,3,FALSE),"") -> حبه | I8: 0 | J8: 100 | K8: 0 | L8: =I8+J8-K8 -> 100 | M8: 250 | N8: =M8*L8 -> 25000 | O8: =IFERROR(N8/L8,"") -> 250 | P8: 20003 | Q8: =IF(P8<>"",VLOOKUP(P8,'العملاءوالموردون والاصناف'!$I$3:$J$6,2,FALSE),"") -> المورد رقم2 | T8: =IF(S8<>"",VLOOKUP(S8,'العملاءوالموردون والاصناف'!$M$3:$N$6,2,FALSE),"")
B9: 10005 | C9: سند ادخال | D9: 45759 | E9: =IF(D9<>"",TEXT(D9,"mmmm"),"") -> April | F9: 10001 | G9: =IF(F9<>"",VLOOKUP(F9,'العملاءوالموردون والاصناف'!$D$3:$F$6,2,FALSE),"") -> صنف1 | H9: =IF(F9<>"",VLOOKUP(F9,'العملاءوالموردون والاصناف'!$D$3:$F$6,3,FALSE),"") -> متر | I9: 0 | J9: 125 | K9: 0 | L9: =I9+J9-K9 -> 125 | M9: 200 | N9: =M9*L9 -> 25000 | O9: =IFERROR(N9/L9,"") -> 200 | P9: 20004 | Q9: =IF(P9<>"",VLOOKUP(P9,'العملاءوالموردون والاصناف'!$I$3:$J$6,2,FALSE),"") -> المورد رقم3 | T9: =IF(S9<>"",VLOOKUP(S9,'العملاءوالموردون والاصناف'!$M$3:$N$6,2,FALSE),"")
B10: 10006 | C10: سند صرف | D10: 45790 | E10: =IF(D10<>"",TEXT(D10,"mmmm"),"") -> May | F10: 10001 | G10: =IF(F10<>"",VLOOKUP(F10,'العملاءوالموردون والاصناف'!$D$3:$F$6,2,FALSE),"") -> صنف1 | H10: =IF(F10<>"",VLOOKUP(F10,'العملاءوالموردون والاصناف'!$D$3:$F$6,3,FALSE),"") -> متر | I10: 0 | K10: 200 | L10: =I10+J10-K10 -> -200 | M10: 266.66667 | N10: =M10*L10 -> -53333.333 | O10: =IFERROR(N10/L10,"") -> 266.66667 | Q10: =IF(P10<>"",VLOOKUP(P10,'العملاءوالموردون والاصناف'!$I$3:$J$6,2,FALSE),"") | R10: 50001 | S10: 30003 | T10: =IF(S10<>"",VLOOKUP(S10,'العملاءوالموردون والاصناف'!$M$3:$N$6,2,FALSE),"") -> عميل 3
B11: 10007 | C11: سند صرف | D11: 45791 | E11: =IF(D11<>"",TEXT(D11,"mmmm"),"") -> May | F11: 10003 | G11: =IF(F11<>"",VLOOKUP(F11,'العملاءوالموردون والاصناف'!$D$3:$F$6,2,FALSE),"") -> صنف3 | H11: =IF(F11<>"",VLOOKUP(F11,'العملاءوالموردون والاصناف'!$D$3:$F$6,3,FALSE),"") -> حبه | I11: 0 | K11: 75 | L11: =I11+J11-K11 -> -75 | M11: 250 | N11: =M11*L11 -> -18750 | O11: =IFERROR(N11/L11,"") -> 250 | R11: 50003 | S11: 30002 | T11: =IF(S11<>"",VLOOKUP(S11,'العملاءوالموردون والاصناف'!$M$3:$N$6,2,FALSE),"") -> عميل 2
E12: =IF(D12<>"",TEXT(D12,"mmmm"),"") | G12: =IF(F12<>"",VLOOKUP(F12,'العملاءوالموردون والاصناف'!$D$3:$F$6,2,FALSE),"") | H12: =IF(F12<>"",VLOOKUP(F12,'العملاءوالموردون والاصناف'!$D$3:$F$6,3,FALSE),"") | L12: =I12+J12-K12 -> 0 | N12: =M12*L12 -> 0 | O12: =IFERROR(N12/L12,"") | Q12: =IF(P12<>"",VLOOKUP(P12,'العملاءوالموردون والاصناف'!$I$3:$J$6,2,FALSE),"") | T12: =IF(S12<>"",VLOOKUP(S12,'العملاءوالموردون والاصناف'!$M$3:$N$6,2,FALSE),"")
E13: =IF(D13<>"",TEXT(D13,"mmmm"),"") | G13: =IF(F13<>"",VLOOKUP(F13,'العملاءوالموردون والاصناف'!$D$3:$F$6,2,FALSE),"") | H13: =IF(F13<>"",VLOOKUP(F13,'العملاءوالموردون والاصناف'!$D$3:$F$6,3,FALSE),"") | L13: =I13+J13-K13 -> 0 | N13: =M13*L13 -> 0 | O13: =IFERROR(N13/L13,"") | Q13: =IF(P13<>"",VLOOKUP(P13,'العملاءوالموردون والاصناف'!$I$3:$J$6,2,FALSE),"") | T13: =IF(S13<>"",VLOOKUP(S13,'العملاءوالموردون والاصناف'!$M$3:$N$6,2,FALSE),"")
E14: =IF(D14<>"",TEXT(D14,"mmmm"),"") | G14: =IF(F14<>"",VLOOKUP(F14,'العملاءوالموردون والاصناف'!$D$3:$F$6,2,FALSE),"") | H14: =IF(F14<>"",VLOOKUP(F14,'العملاءوالموردون والاصناف'!$D$3:$F$6,3,FALSE),"") | L14: =I14+J14-K14 -> 0 | N14: =M14*L14 -> 0 | O14: =IFERROR(N14/L14,"") | Q14: =IF(P14<>"",VLOOKUP(P14,'العملاءوالموردون والاصناف'!$I$3:$J$6,2,FALSE),"") | T14: =IF(S14<>"",VLOOKUP(S14,'العملاءوالموردون والاصناف'!$M$3:$N$6,2,FALSE),"")
E15: =IF(D15<>"",TEXT(D15,"mmmm"),"") | G15: =IF(F15<>"",VLOOKUP(F15,'العملاءوالموردون والاصناف'!$D$3:$F$6,2,FALSE),"") | H15: =IF(F15<>"",VLOOKUP(F15,'العملاءوالموردون والاصناف'!$D$3:$F$6,3,FALSE),"") | L15: =I15+J15-K15 -> 0 | N15: =M15*L15 -> 0 | O15: =IFERROR(N15/L15,"") | Q15: =IF(P15<>"",VLOOKUP(P15,'العملاءوالموردون والاصناف'!$I$3:$J$6,2,FALSE),"") | T15: =IF(S15<>"",VLOOKUP(S15,'العملاءوالموردون والاصناف'!$M$3:$N$6,2,FALSE),"")
E16: =IF(D16<>"",TEXT(D16,"mmmm"),"") | G16: =IF(F16<>"",VLOOKUP(F16,'العملاءوالموردون والاصناف'!$D$3:$F$6,2,FALSE),"") | H16: =IF(F16<>"",VLOOKUP(F16,'العملاءوالموردون والاصناف'!$D$3:$F$6,3,FALSE),"") | L16: =I16+J16-K16 -> 0 | N16: =M16*L16 -> 0 | O16: =IFERROR(N16/L16,"") | Q16: =IF(P16<>"",VLOOKUP(P16,'العملاءوالموردون والاصناف'!$I$3:$J$6,2,FALSE),"") | T16: =IF(S16<>"",VLOOKUP(S16,'العملاءوالموردون والاصناف'!$M$3:$N$6,2,FALSE),"")
E17: =IF(D17<>"",TEXT(D17,"mmmm"),"") | G17: =IF(F17<>"",VLOOKUP(F17,'العملاءوالموردون والاصناف'!$D$3:$F$6,2,FALSE),"") | H17: =IF(F17<>"",VLOOKUP(F17,'العملاءوالموردون والاصناف'!$D$3:$F$6,3,FALSE),"") | L17: =I17+J17-K17 -> 0 | N17: =M17*L17 -> 0 | O17: =IFERROR(N17/L17,"") | Q17: =IF(P17<>"",VLOOKUP(P17,'العملاءوالموردون والاصناف'!$I$3:$J$6,2,FALSE),"") | T17: =IF(S17<>"",VLOOKUP(S17,'العملاءوالموردون والاصناف'!$M$3:$N$6,2,FALSE),"")
E18: =IF(D18<>"",TEXT(D18,"mmmm"),"") | G18: =IF(F18<>"",VLOOKUP(F18,'العملاءوالموردون والاصناف'!$D$3:$F$6,2,FALSE),"") | H18: =IF(F18<>"",VLOOKUP(F18,'العملاءوالموردون والاصناف'!$D$3:$F$6,3,FALSE),"") | L18: =I18+J18-K18 -> 0 | N18: =M18*L18 -> 0 | O18: =IFERROR(N18/L18,"") | Q18: =IF(P18<>"",VLOOKUP(P18,'العملاءوالموردون والاصناف'!$I$3:$J$6,2,FALSE),"") | T18: =IF(S18<>"",VLOOKUP(S18,'العملاءوالموردون والاصناف'!$M$3:$N$6,2,FALSE),"")
E19: =IF(D19<>"",TEXT(D19,"mmmm"),"") | G19: =IF(F19<>"",VLOOKUP(F19,'العملاءوالموردون والاصناف'!$D$3:$F$6,2,FALSE),"") | H19: =IF(F19<>"",VLOOKUP(F19,'العملاءوالموردون والاصناف'!$D$3:$F$6,3,FALSE),"") | L19: =I19+J19-K19 -> 0 | N19: =M19*L19 -> 0 | O19: =IFERROR(N19/L19,"") | Q19: =IF(P19<>"",VLOOKUP(P19,'العملاءوالموردون والاصناف'!$I$3:$J$6,2,FALSE),"") | T19: =IF(S19<>"",VLOOKUP(S19,'العملاءوالموردون والاصناف'!$M$3:$N$6,2,FALSE),"")
E20: =IF(D20<>"",TEXT(D20,"mmmm"),"") | G20: =IF(F20<>"",VLOOKUP(F20,'العملاءوالموردون والاصناف'!$D$3:$F$6,2,FALSE),"") | H20: =IF(F20<>"",VLOOKUP(F20,'العملاءوالموردون والاصناف'!$D$3:$F$6,3,FALSE),"") | L20: =I20+J20-K20 -> 0 | N20: =M20*L20 -> 0 | O20: =IFERROR(N20/L20,"") | Q20: =IF(P20<>"",VLOOKUP(P20,'العملاءوالموردون والاصناف'!$I$3:$J$6,2,FALSE),"") | T20: =IF(S20<>"",VLOOKUP(S20,'العملاءوالموردون والاصناف'!$M$3:$N$6,2,FALSE),"")
E21: =IF(D21<>"",TEXT(D21,"mmmm"),"") | G21: =IF(F21<>"",VLOOKUP(F21,'العملاءوالموردون والاصناف'!$D$3:$F$6,2,FALSE),"") | H21: =IF(F21<>"",VLOOKUP(F21,'العملاءوالموردون والاصناف'!$D$3:$F$6,3,FALSE),"") | L21: =I21+J21-K21 -> 0 | N21: =M21*L21 -> 0 | O21: =IFERROR(N21/L21,"") | Q21: =IF(P21<>"",VLOOKUP(P21,'العملاءوالموردون والاصناف'!$I$3:$J$6,2,FALSE),"") | T21: =IF(S21<>"",VLOOKUP(S21,'العملاءوالموردون والاصناف'!$M$3:$N$6,2,FALSE),"")
E22: =IF(D22<>"",TEXT(D22,"mmmm"),"") | G22: =IF(F22<>"",VLOOKUP(F22,'العملاءوالموردون والاصناف'!$D$3:$F$6,2,FALSE),"") | H22: =IF(F22<>"",VLOOKUP(F22,'العملاءوالموردون والاصناف'!$D$3:$F$6,3,FALSE),"") | L22: =I22+J22-K22 -> 0 | N22: =M22*L22 -> 0 | O22: =IFERROR(N22/L22,"") | Q22: =IF(P22<>"",VLOOKUP(P22,'العملاءوالموردون والاصناف'!$I$3:$J$6,2,FALSE),"") | T22: =IF(S22<>"",VLOOKUP(S22,'العملاءوالموردون والاصناف'!$M$3:$N$6,2,FALSE),"")
E23: =IF(D23<>"",TEXT(D23,"mmmm"),"") | G23: =IF(F23<>"",VLOOKUP(F23,'العملاءوالموردون والاصناف'!$D$3:$F$6,2,FALSE),"") | H23: =IF(F23<>"",VLOOKUP(F23,'العملاءوالموردون والاصناف'!$D$3:$F$6,3,FALSE),"") | L23: =I23+J23-K23 -> 0 | N23: =M23*L23 -> 0 | O23: =IFERROR(N23/L23,"") | Q23: =IF(P23<>"",VLOOKUP(P23,'العملاءوالموردون والاصناف'!$I$3:$J$6,2,FALSE),"") | T23: =IF(S23<>"",VLOOKUP(S23,'العملاءوالموردون والاصناف'!$M$3:$N$6,2,FALSE),"")
E24: =IF(D24<>"",TEXT(D24,"mmmm"),"") | G24: =IF(F24<>"",VLOOKUP(F24,'العملاءوالموردون والاصناف'!$D$3:$F$6,2,FALSE),"") | H24: =IF(F24<>"",VLOOKUP(F24,'العملاءوالموردون والاصناف'!$D$3:$F$6,3,FALSE),"") | L24: =I24+J24-K24 -> 0 | N24: =M24*L24 -> 0 | O24: =IFERROR(N24/L24,"") | Q24: =IF(P24<>"",VLOOKUP(P24,'العملاءوالموردون والاصناف'!$I$3:$J$6,2,FALSE),"") | T24: =IF(S24<>"",VLOOKUP(S24,'العملاءوالموردون والاصناف'!$M$3:$N$6,2,FALSE),"")
I26: =SUBTOTAL(9,I5:I24) -> 0 | J26: =SUBTOTAL(9,J5:J24) -> 575 | K26: =SUBTOTAL(9,K5:K24) -> 275 | L26: =SUBTOTAL(9,L5:L24) -> 300 | N26: =SUBTOTAL(9,N5:N24) -> 77916.667 | O26: =IFERROR(N26/L26,"") -> 259.72222

Sheet العملاءوالموردون والاصناف
D3: كود الصنف | E3: اسم الصنف | F3: وحده القياس | I3: كود المورد | J3: اسم المورد | M3: اسم العميل | N3: كود العميل
D4: 10001 | E4: صنف1 | F4: متر | I4: 20002 | J4: المورد رقم1 | M4: 30001 | N4: عميل 1
D5: 10002 | E5: صنف2 | F5: كيلو | I5: 20003 | J5: المورد رقم2 | M5: 30002 | N5: عميل 2
D6: 10003 | E6: صنف3 | F6: حبه | I6: 20004 | J6: المورد رقم3 | M6: 30003 | N6: عميل 3

Sheet الايجارات
B3: الوصف | C3: المبلغ | D3: من | E3: الي | F3: 45658 | G3: 45689 | H3: 45717 | I3: 45748 | J3: 45778 | K3: 45809 | L3: 45839 | M3: 45870 | N3: 45901 | O3: 45931 | P3: 45962 | Q3: 45992 | R3: اجمالي 2025 | S3: المبتقي | T3: 46023 | U3: 46054 | V3: 46082 | W3: 46113 | X3: 46143 | Y3: 46174 | Z3: 46204 | AA3: 46235 | AB3: 46266 | AC3: 46296 | AD3: 46327 | AE3: 46357 | AF3: اجمالي 2025 | AG3: المبتقي
B4: سداد ايجار المستودع الرئيسي | C4: 60000 | D4: 45658 | E4: 31/12/2025 | F4: =$C$4/12 -> 5000 | G4: =$C$4/12 -> 5000 | H4: =$C$4/12 -> 5000 | I4: =$C$4/12 -> 5000 | J4: =$C$4/12 -> 5000 | K4: =$C$4/12 -> 5000 | L4: =$C$4/12 -> 5000 | M4: =$C$4/12 -> 5000 | ... Q4: =$C$4/12 -> 5000 | R4: =SUM(F4:Q4) -> 60000 | S4: =R4-C4 -> 0 | AF4: =SUM(T4:AE4) -> 0 | AG4: =S4-AF4 -> 0
B5: سداد ايجار معدات | C5: 75000 | D5: 45658 | E5: 31/12/2025 | F5: =$C$5/12 -> 6250 | G5: =$C$5/12 -> 6250 | H5: =$C$5/12 -> 6250 | I5: =$C$5/12 -> 6250 | J5: =$C$5/12 -> 6250 | K5: =$C$5/12 -> 6250 | L5: =$C$5/12 -> 6250 | M5: =$C$5/12 -> 6250 | ... Q5: =$C$5/12 -> 6250 | R5: =SUM(F5:Q5) -> 75000 | S5: =R5-C5 -> 0 | AF5: =SUM(T5:AE5) -> 0 | AG5: =S5-AF5 -> 0
B6: الاجمالي | C6: =C4+C5 -> 135000 | F6: =F4+F5 -> 11250 | G6: =G4+G5 -> 11250 | H6: =H4+H5 -> 11250 | I6: =I4+I5 -> 11250 | J6: =J4+J5 -> 11250 | K6: =K4+K5 -> 11250 | L6: =L4+L5 -> 11250 | M6: =M4+M5 -> 11250 | ... Q6: =Q4+Q5 -> 11250 | R6: =SUM(F6:Q6) -> 135000 | S6: =R6-C6 -> 0 | T6: =T4+T5 -> 0 | U6: =U4+U5 -> 0 | V6: =V4+V5 -> 0 | W6: =W4+W5 -> 0 | X6: =X4+X5 -> 0 | Y6: =Y4+Y5 -> 0 | Z6: =Z4+Z5 -> 0 | AA6: =AA4+AA5 -> 0 | ... AE6: =AE4+AE5 -> 0 | AF6: =SUM(T6:AE6) -> 0 | AG6: =S6-AF6 -> 0

Sheet الاهلاك
I2: 2025
B3: كود الاصل | C3: الوصف | D3: تاريخ الشراء | E3: رقم القيد | F3: معدل الاهلاك | G3: القيمه | H3: مجمع الاهلاك السابق | I3: الاهلاك السنوي | J3: مجمع الاهلاك الحالي | K3: صافي قيمه الاصل
B4: A-001 | C4: سياره رقم**** | D4: 45695 | F4: 0.2 | G4: 100000 | H4: 0 | I4: =G4*F4*6/12 -> 10000 | J4: =H4+I4 -> 10000 | K4: =G4-J4 -> 90000
B5: B-001 | C5: احهزه حاسب | D5: 15/2/2025 | F5: 0.2 | G5: 50000 | H5: 0 | I5: =G5*F5*3/12 -> 2500 | J5: =H5+I5 -> 2500 | K5: =G5-J5 -> 47500
B6: C-001 | C6: الات ومعدات | D6: 18/2/2025 | F6: 0.2 | G6: 75000 | H6: 0 | I6: =G6*F6*3/12 -> 3750 | J6: =H6+I6 -> 3750 | K6: =G6-J6 -> 71250
G7: =SUM(G4:G6) -> 225000 | H7: =SUM(H4:H6) -> 0 | I7: =SUM(I4:I6) -> 16250 | J7: =SUM(J4:J6) -> 16250 | K7: =SUM(K4:K6) -> 208750
